INFO:urllib3.connectionpool:Starting new HTTPS connection (1): www.jbhifi.com.au
DEBUG:urllib3.connectionpool:"HEAD /whitegoods-appliances/all-whitegoods--appliances/oral-b-eb20-2/oral-b-precision-clean-refill-2-pack/21029/ HTTP/1.1" 200 0
INFO:urllib3.connectionpool:Starting new HTTPS connection (1): www.jbhifi.com.au
DEBUG:urllib3.connectionpool:"GET /whitegoods-appliances/all-whitegoods--appliances/oral-b-eb20-2/oral-b-precision-clean-refill-2-pack/21029/ HTTP/1.1" 200 24258
INFO:urllib3.connectionpool:Starting new HTTPS connection (1): www.jbhifi.com.au
DEBUG:urllib3.connectionpool:"HEAD /whitegoods-appliances/kitchen-appliances/breville/breville-the-kinetix-pro-blender/33855/ HTTP/1.1" 200 0
INFO:urllib3.connectionpool:Starting new HTTPS connection (1): www.jbhifi.com.au
DEBUG:urllib3.connectionpool:"GET /whitegoods-appliances/kitchen-appliances/breville/breville-the-kinetix-pro-blender/33855/ HTTP/1.1" 200 26491
INFO:urllib3.connectionpool:Starting new HTTPS connection (1): www.jbhifi.com.au
DEBUG:urllib3.connectionpool:"HEAD /whitegoods-appliances/vacuums-floor-cleaners/dyson/dyson-soft-dusting-brush/30055/ HTTP/1.1" 200 0
INFO:urllib3.connectionpool:Starting new HTTPS connection (1): www.jbhifi.com.au
ERROR:root:ERROR
Traceback (most recent call last):
  File "/usr/lib/python3/dist-packages/urllib3/connectionpool.py", line 516, in urlopen
    body=body, headers=headers)
  File "/usr/lib/python3/dist-packages/urllib3/connectionpool.py", line 304, in _make_request
    self._validate_conn(conn)
  File "/usr/lib/python3/dist-packages/urllib3/connectionpool.py", line 724, in _validate_conn
    conn.connect()
  File "/usr/lib/python3/dist-packages/urllib3/connection.py", line 203, in connect
    conn = self._new_conn()
  File "/usr/lib/python3/dist-packages/urllib3/connection.py", line 133, in _new_conn
    (self.host, self.port), self.timeout, **extra_kw)
  File "/usr/lib/python3/dist-packages/urllib3/util/connection.py", line 87, in create_connection
    raise err
  File "/usr/lib/python3/dist-packages/urllib3/util/connection.py", line 78, in create_connection
    sock.connect(sa)
TimeoutError: [Errno 110] Connection timed out

During handling of the above exception, another exception occurred:

Traceback (most recent call last):
  File "/usr/lib/python3/dist-packages/requests/adapters.py", line 362, in send
    timeout=timeout
  File "/usr/lib/python3/dist-packages/urllib3/connectionpool.py", line 559, in urlopen
    _pool=self, _stacktrace=stacktrace)
  File "/usr/lib/python3/dist-packages/urllib3/util/retry.py", line 245, in increment
    raise six.reraise(type(error), error, _stacktrace)
  File "/usr/lib/python3/dist-packages/six.py", line 624, in reraise
    raise value.with_traceback(tb)
  File "/usr/lib/python3/dist-packages/urllib3/connectionpool.py", line 516, in urlopen
    body=body, headers=headers)
  File "/usr/lib/python3/dist-packages/urllib3/connectionpool.py", line 304, in _make_request
    self._validate_conn(conn)
  File "/usr/lib/python3/dist-packages/urllib3/connectionpool.py", line 724, in _validate_conn
    conn.connect()
  File "/usr/lib/python3/dist-packages/urllib3/connection.py", line 203, in connect
    conn = self._new_conn()
  File "/usr/lib/python3/dist-packages/urllib3/connection.py", line 133, in _new_conn
    (self.host, self.port), self.timeout, **extra_kw)
  File "/usr/lib/python3/dist-packages/urllib3/util/connection.py", line 87, in create_connection
    raise err
  File "/usr/lib/python3/dist-packages/urllib3/util/connection.py", line 78, in create_connection
    sock.connect(sa)
urllib3.exceptions.ProtocolError: ('Connection aborted.', TimeoutError(110, 'Connection timed out'))

During handling of the above exception, another exception occurred:

Traceback (most recent call last):
  File "/home/tupperware/JBHIFIWebCrawler/Programs/JBHIFIPriceAnalyser.py", line 211, in <module>
    database_analyser()
  File "/home/tupperware/JBHIFIWebCrawler/Programs/JBHIFIPriceAnalyser.py", line 118, in database_analyser
    productSourceCode = requests.get(url)
  File "/usr/lib/python3/dist-packages/requests/api.py", line 60, in get
    return request('get', url, **kwargs)
  File "/usr/lib/python3/dist-packages/requests/api.py", line 49, in request
    return session.request(method=method, url=url, **kwargs)
  File "/usr/lib/python3/dist-packages/requests/sessions.py", line 457, in request
    resp = self.send(prep, **send_kwargs)
  File "/usr/lib/python3/dist-packages/requests/sessions.py", line 569, in send
    r = adapter.send(request, **kwargs)
  File "/usr/lib/python3/dist-packages/requests/adapters.py", line 407, in send
    raise ConnectionError(err, request=request)
requests.exceptions.ConnectionError: ('Connection aborted.', TimeoutError(110, 'Connection timed out'))
